Workbook

Sheet Vehiculos
A1: PLACA | B1: TIPOVEHICULO | C1: PROPIETARIO | D1: FECHA | E1: DIA DE PAGO | F1: COLOR | G1: MONTO
A2: 6262IXG | B2: VAGONETA PEUGOT | C2: MARIA ELENA MERCADO | D2: 45151 | E2: 13 DE CADA MES | F2: VAGONETA GUINDA | G2: 150
A3: 2361KNA | B3: AUTO NISAN | C3: ANDREA | D3: 45152 | E3: 14 DE CADA MES | F3: AUTO PLOMO | G3: 150
A4: 1758GXK | B4: TOYOTA CALDINA | C4: EDWIN | D4: 45144 | E4: 6 DE CADA MES | F4: VAGONETA GUINDA | G4: 150
A5: 2358NDY | B5: MISTUBISHI LANCER | C5: DIMAR | D5: 45746 | E5: 1 DE CADA MES | F5: VAGONETA BLANCO | G5: 150
A6: 2235ICI | B6: MOTONETA | C6: DELMIRA ORTEGA | D6: 45935 | E6: 5 de cada mes | F6: GUINDO | G6: 60
A7: 3628SKD | B7: VAGONETA SUZUKI | C7: EFRAIN | D7: 46069 | E7: 16 DE CADA MES | F7: GUINDO | G7: 180

Sheet REGISTROPAGOS
A1: PLACA | B1: FECHAPAGO | C1: MONTO | D1: NO PAGO | E1: MES | F1: OBSERVACIONES | G1: ANIO
A2: 2358NDY | B2: 46030 | C2: 150 | D2: 0 | E2: ENERO | G2: 2026
A3: 2235ICI | B3: 46048 | C3: 60 | D3: 0 | E3: ENERO | G3: 2026
A4: 2358NDY | B4: 46055 | C4: 150 | D4: 0 | E4: FEBRERO | G4: 2026
A5: 6262IXG | B5: 46025 | C5: 160 | D5: 0 | E5: ENERO | G5: 2026
A6: 3628SKD | B6: 46069 | C6: 180 | D6: 0 | E6: FEBRERO | F6: ADELANTO | G6: 2026
A7: 2361KNA | B7: 46036 | C7: 150 | D7: 0 | E7: ENERO | G7: 2026
A8: 2361KNA | B8: 46065 | C8: 55 | D8: 0 | E8: FEBRERO | F8: SE RETIRA DEBE LLAVE | G8: 2026
A9: 6262IXG | B9: 46059 | C9: 150 | D9: 0 | E9: FEBRERO | G9: 2026
A10: 2358NDY | B10: 46086 | C10: 150 | D10: 0 | E10: MARZO | G10: 2026
A11: 6262IXG | B11: 46099 | C11: 150 | D11: 0 | E11: MARZO | G11: 2026
A12: 2235ICI | B12: 46066 | C12: 60 | D12: 0 | E12: FEBRERO | G12: 2026
A13: 2235ICI | B13: 46095 | C13: 60 | D13: 0 | E13: MARZO | G13: 2026
A14: 1758GXK | B14: 46001 | C14: 0 | D14: 150 | E14: DICIEMBRE | F14: NO PAGO | G14: 2025
A15: 1758GXK | B15: 46032 | C15: =DETALLE!I83 -> 0 | D15: 300 | E15: ENERO | F15: NO PAGO | G15: 2026
A16: 1758GXK | B16: 46063 | C16: =DETALLE!I84 -> 0 | D16: 450 | E16: FEBRERO | F16: NO PAGO | G16: 2026
A17: 1758GXK | B17: 42439 | C17: =DETALLE!I85 -> 0 | D17: 500 | E17: MARZO | F17: NO PAGO | G17: 2026
A18: 1758GXK | B18: 46122 | C18: =DETALLE!I86 -> 0 | D18: 650 | E18: ABRIL | F18: NO PAGO MOTOS DESDE ENE 200 BS, TOTAL 850 | G18: 2026
A19: 6262IXG | B19: 46136 | C19: 150 | D19: 0 | E19: ABRIL | G19: 2026
A20: 6262IXG | B20: 46143 | C20: =DETALLE!I89 -> 0 | D20: 150 | E20: MAYO | G20: 2026
A21: 6262IXG | B21: 46176 | C21: 150 | D21: 150 | E21: JUNIO | G21: 2026
A22: 2358NDY | B22: 46118 | C22: 150 | D22: 0 | E22: ABRIL | G22: 2026
A23: 2358NDY | B23: 46150 | C23: 150 | D23: 0 | E23: MAYO | G23: 2026
A24: 2358NDY | B24: 46023 | C24: 150 | D24: 0 | E24: JUNIO | G24: 2026
A25: 2235ICI | B25: 46144 | C25: 60 | D25: 0 | E25: MAYO | G25: 2026
A26: 2235ICI | B26: 46177 | C26: 60 | D26: 0 | E26: JUNIO | G26: 2026
A27: 2235ICI | B27: 46207 | C27: 60 | D27: 0 | E27: JULIO | F27: DE JUNIO Y JULIO | G27: 2026
A28: 1758GXK | B28: 46144 | C28: 300 | D28: 400 | E28: MAYO | F28: MAS MOTOCICLETA 50+350 | G28: 2026
A29: 1758GXK | B29: 46183 | C29: 0 | D29: 600 | E29: JUNIO | F29: MAS MOTOCICLETA 150+50+400 | G29: 2026
A30: 1758GXK | B30: 46213 | C30: =DETALLE!I99 -> 0 | D30: 800 | E30: JULIO | F30: MAS MOTOCICLETA 150+50+600 | G30: 2026

Sheet REGISTROPAGOS 2025
A1: PLACA | B1: FECHAPAGO | C1: MONTO | D1: NO PAGO | E1: MES | F1: OBSERVACIONES | G1: ANIO
A2: 2361KNA | B2: 45675 | C2: 150 | D2: 0 | E2: ENERO | G2: 2025
A3: 2361KNA | B3: 45701 | C3: 150 | D3: 0 | E3: FEBRERO | G3: 2025
A4: 2361KNA | B4: 45726 | C4: 150 | D4: 0 | E4: MARZO | G4: 2025
A5: 2361KNA | B5: 45762 | C5: 150 | D5: 0 | E5: ABRIL | G5: 2025
A6: 6262IXG | B6: 45763 | C6: 0 | D6: 0 | E6: ABRIL | F6: INGRESO | G6: 2025
A7: 1758GXK | B7: 45667 | C7: 0 | D7: 1000 | E7: DICIMBRE | F7: Tiene pendientes desde 2024 | G7: 2025
A8: 1758GXK | B8: 45698 | C8: 0 | D8: 1150 | E8: ENERO | G8: 2025
A9: 1758GXK | B9: 45726 | C9: 400 | D9: 900 | E9: FEBRERO | G9: 2025
A10: 1758GXK | B10: 45757 | C10: 300 | D10: 550 | E10: MARZO | G10: 2025
A11: 1758GXK | B11: 45784 | C11: 500 | D11: 50 | E11: ABRIL | F11: Para el siguiente mes arrastra 50 | G11: 2025
A12: 2358NDY | B12: 45778 | C12: 150 | D12: 0 | E12: ABRIL | F12: Primer pago | G12: 2025
A13: 2361KNA | B13: 45791 | C13: 150 | D13: 0 | E13: MAYO | G13: 2025
A14: 6262IXG | B14: 45795 | C14: 150 | D14: 0 | E14: MAYO | G14: 2025
A15: 1758GXK | B15: 45812 | C15: 200 | D15: 150 | E15: MAYO | G15: 2025
A16: 2358NDY | B16: 45810 | C16: 150 | D16: 0 | E16: MAYO | G16: 2025
A17: 2361KNA | B17: 45826 | C17: 150 | D17: 0 | E17: JUNIO | G17: 2025
A18: 6262IXG | B18: 45826 | C18: 150 | D18: 0 | E18: JUNIO | G18: 2025
A19: 2358NDY | B19: 45841 | C19: 150 | D19: 0 | E19: JUNIO | G19: 2025
A20: 2235ICI | B20: 45935 | C20: 60 | D20: 0 | E20: OCTUBRE | G20: 2025
A21: 2361KNA | B21: 45848 | C21: 150 | D21: 0 | E21: JULIO | G21: 2025
A22: 6262IXG | B22: 45858 | C22: 170 | D22: 0 | E22: JULIO | F22: 20BS ALQUILER 2 DÍAS | G22: 2025
A23: 2358NDY | B23: 45872 | C23: 150 | D23: 0 | E23: JULIO | G23: 2025
A24: 6262IXG | B24: 45885 | C24: 180 | D24: 0 | E24: AGOSTO | F24: 30BS ALQUILER 2 DÍAS | G24: 2025
A25: 2361KNA | B25: 45885 | C25: 150 | D25: 0 | E25: AGOSTO | G25: 2025
A26: 1758GXK | B26: 45905 | C26: 200 | D26: 250 | E26: JUNIO | F26: Debe 250 +150 octubre | G26: 2025
A27: 2361KNA | B27: 45918 | C27: 150 | D27: 0 | E27: SEPTIEMBRE | G27: 2025
A28: 6262IXG | B28: 45923 | C28: 150 | D28: 0 | E28: SEPTIEMBRE | G28: 2025
A29: 2358NDY | B29: 45910 | C29: 150 | D29: 0 | E29: AGOSTO | G29: 2025
A30: 2358NDY | B30: 45932 | C30: 150 | D30: 0 | E30: SEPTIEMBRE | G30: 2025
A31: 2361KNA | B31: 45947 | C31: 150 | D31: 0 | E31: OCTUBRE | G31: 2025
A32: 6262IXG | B32: 45956 | C32: 150 | D32: 0 | E32: OCTUBRE | G32: 2025
A33: 1758GXK | B33: 45940 | C33: 150 | D33: 400 | F33: MESES IRREGULARES | G33: 2025
A34: 1758GXK | B34: 45963 | C34: 400 | D34: 0 | E34: OCTUBRE | F34: NIVELADO | G34: 2025
A35: 2358NDY | B35: 45965 | C35: 150 | D35: 0 | E35: OCTUBRE | G35: 2025
A36: 2235ICI | B36: 45975 | C36: 60 | D36: 0 | E36: NOVIEMBRE | G36: 2025
A37: 2361KNA | B37: 45975 | C37: 150 | D37: 0 | E37: NOVIEMBRE | G37: 2025
A38: 2361KNA | B38: 46006 | C38: 150 | D38: 0 | E38: DICIEMBRE | G38: 2025
A39: 2358NDY | B39: 45998 | C39: 150 | D39: 0 | E39: NOVIEMBRE | G39: 2025
A40: 6262IXG | B40: 45990 | C40: 150 | D40: 0 | E40: NOVIEMBRE | G40: 2025
...

Sheet DETALLE
B1: CODIGO | C1: NBSJB515 | H1: CODIGO | I1: BOESFB245 | N1: CODIGO | O1: FEXJO544
B2: ESTADO | C2: VIGENTE | E2: NOMBRE | F2: MARIA ELENA MERCADO | H2: ESTADO | I2: VIGENTE | K2: NOMBRE | L2: ANDREA | N2: ESTADO | O2: VIGENTE | Q2: NOMBRE | R2: EDWIN MONTECINOS
B3: VEHICULO | C3: VAGONETA PEUGOT | H3: VEHICULO | I3: AUTO NISAN | N3: VEHICULO | O3: NISAN VAGON
B4: COLOR | C4: GUINDO | H4: COLOR | I4: PLOMO | N4: COLOR
B5: PLACA | E5: CEL | F5: 70914404 | H5: PLACA | I5: 2361KNA | K5: CELULAR | L5: 6119134 | N5: PLACA | O5: 1758GXK | Q5: CELULAR | R5: 72895433
B6: INGRESO | C6: 0.8125 | D6: SALIDA | E6: 0.3125 | H6: INGRESO | I6: 0.33333333 | J6: SALIDA | K6: 0.33333333 | N6: INGRESO | O6: 0.95833333 | P6: SALE | Q6: 0.29166667
B7: FECHA | C7: MONTO | D7: ACUMULADO | E7: DEBE | F7: OBSERVACIONES | H7: FECHA | I7: MONTO | J7: ACUMULADO | K7: DEBE | L7: OBSERVACIONES | N7: FECHA | O7: MONTO | P7: DEBE | Q7: ACUMULADO | R7: OBSERVACIONES
B8: 45763 | F8: INGRESO PAGA CADA 16 | H8: 45121 | I8: 50 | J8: 0 | K8: 0 | L8: ADELANTO DE JULIO | N8: 45086 | O8: 500 | P8: 1500 | Q8: =P8+O8 -> 2000 | R8: 2000 HASTA JUNIO INCLUYE MOTOS
B9: 45795 | C9: 150 | D9: 0 | E9: 0 | F9: PRIMER MES | H9: 45122 | I9: 100 | J9: 0 | K9: 0 | L9: pagado julio | N9: 45115 | O9: 300 | P9: =P8-O9 -> 1200 | Q9: 1500 | R9: DEBE 1500 NO PAGO DE JULIO 150
B10: 45826 | C10: 150 | D10: 0 | E10: 0 | H10: 45183 | I10: 150 | J10: 0 | K10: 0 | N10: 45145 | O10: 500 | P10: =P9-O10 -> 700 | Q10: 850 | R10: MAS JULIO 1200+150 = 1350-500=850
B11: 45858 | C11: 170 | D11: 0 | E11: 0 | F11: 20 BS ALQUILER 2 DIAS | H11: 45209 | I11: 150 | J11: 0 | K11: 0 | N11: AGOSTO | O11: 0 | P11: 1000 | Q11: 1000 | R11: DEBE AGOSTO 850+150=1000
B12: 45885 | C12: 180 | D12: 0 | E12: 0 | F12: 30 BS ALQUILER 2 DIAS | H12: 45244 | I12: 150 | J12: 0 | K12: 0 | N12: SEPTIEMBRE | O12: 0 | P12: 1150 | Q12: 1150 | R12: NO PAGO DE SEPT. 1000+150=1150
B13: 45923 | C13: 150 | D13: 0 | E13: 0 | H13: 45275 | I13: 150 | N13: OCTUBRE | O13: 300 | P13: =P12-O13 -> 850 | Q13: =P13+150 -> 1000 | R13: PAGO EN MES OCT. 1150-300=850 MAS NOV 150 =1000
B14: 45956 | C14: 150 | D14: 0 | E14: 0 | H14: 45306 | I14: 150 | J14: 0 | K14: 0 | O14: 250 | Q14: 750 | R14: no debe
H15: 45337 | I15: 150 | J15: 0 | K15: 0 | N15: 45301 | O15: 150 | Q15: 0
H16: 45365 | I16: 150 | J16: 0 | K16: 0 | N16: 45341 | O16: 150 | Q16: 300 | R16: debe
H17: 45399 | I17: 150 | J17: 0 | K17: 0 | N17: 45366 | O17: 300 | P17: 150 | R17: del mes de marzo
H18: 45429 | I18: 150 | N18: Abril | P18: 150 | Q18: =P18+P17 -> 300 | R18: debe 300
H19: 45454 | I19: 150 | L19: JULIO EN MECANICO | N19: mayo | P19: 150 | Q19: =Q18+P19 -> 450 | R19: NO PAGO
H20: 45514 | I20: 150 | N20: Junio | P20: 150 | Q20: =Q19+P20 -> 600 | R20: NO PAGO
H21: 45545 | I21: 150 | N21: Julio | Q21: =Q20+P21 -> 600 | R21: VEHICULO MAL
H22: 45575 | I22: 150 | N22: Julio | O22: 150 | P22: =Q21-O22 -> 450 | Q22: 450 | R22: PAGO DE UN MES
H23: 45606 | I23: 150 | N23: AGOSTO | O23: 200 | P23: 250 | Q23: 250 | R23: PAGO 200, DEBE 250
H24: 45641 | I24: 150 | N24: FECHA | O24: MONTO | P24: DEBE | Q24: ACUMULADO | R24: OBSERVACIONES
N25: 2024
H26: 45675 | I26: 150 | N26: Abril | P26: 150 | Q26: 300 | R26: debe 300
H27: 45701 | I27: 150 | N27: mayo | P27: 150 | Q27: 450 | R27: NO PAGO
H28: 45726 | I28: 150 | N28: Junio | P28: 150 | Q28: 600 | R28: NO PAGO
H29: 45762 | I29: 150 | N29: Julio | Q29: 600 | R29: VEHICULO MAL
H30: 45791 | I30: 150 | N30: Julio | O30: 150 | P30: 450 | Q30: 450 | R30: PAGO DE UN MES
H31: 45819 | I31: 150 | N31: AGOSTO | O31: 200 | P31: 250 | Q31: 250 | R31: PAGO 200, DEBE 250
H32: 45848 | I32: 150 | N32: SEPTIEMBRE | O32: 0 | P32: 250 | Q32: 400 | R32: 250+150 DEBE 400
H33: 45885 | I33: 150 | N33: OCTUBRE | O33: 0 | P33: 400 | Q33: 550
H34: 45918 | I34: 150 | N34: NOVIEMBRE | O34: 0 | P34: 550 | Q34: 700 | R34: 550+150 DEBE 700
H35: 45947 | I35: 150 | N35: DICIEMBRE | O35: 700 | P35: 150 | Q35: 850 | R35: NO PAGO
N36: 2025 pago hasta fin de mes
N37: MES | O37: CANCELO | P37: PAGO MES | Q37: DEBE | R37: OBSERVACIONES
N38: ENERO | O38: 0 | P38: 150 | Q38: 1000 | R38: 850+150 =1000 no pago del mes
N39: FEBRERO | O39: 0 | P39: 150 | Q39: 1150 | R39: 1000+150=1150 no pago del mes
N40: MARZO | O40: 400 | P40: 150 | Q40: 900 | R40: 1150-400 =750 mas 150 del mes =900
...

Sheet motos
B3: VEHICULO | C3: MOTO CELESTE | G3: VEHICULO | H3: MOTO VERDE
B4: PLACA | C4: SIN PLACA HIJO MAYOR DE DON EWDIN | G4: PLACA | H4: SIN PLACA HIJO MENOR DE DON EDWIN
B6: FECHA | C6: MONTO | D6: DEBE | E6: OBSERVACIONES | G6: FECHA | H6: MONTO | I6: DEBE | J6: OBSERVACIONES
B7: 45146 | C7: 50 | D7: 10 | E7: DEL ANTERIOR MES DEBE 10 | G7: 45113 | I7: 20 | J7: DEL ANTERIOR MES DEBE 20
B8: AGOSTO | C8: - | D8: 50 | E8: DEBE AGOSTO 50 TOTAL 60 | G8: AGOSTO | H8: 0 | I8: 50 | J8: DEBE AGOTO 50 TOTAL 70
B9: SEPTIEMBRE | C9: - | D9: 100 | E9: PAGO EN MES DE OCTUBRE 50 | G9: SEPTIEMBRE | H9: 0 | I9: 120 | J9: DE SEPT. 70+50=120
B10: 45201 | C10: 50 | D10: 50 | G10: OCTUBRE | H10: 20 | I10: 100 | J10: PAGO EN EL
B11: NOV | C11: 50 | G11: 45201 | H11: 25 | I11: 75 | J11: TRANSCURSO
B12: DIC | C12: 50 | D12: 150 | E12: DEBE DE TRES MESES | G12: 45209 | H12: 25 | I12: 50 | J12: DEL MES DE OCTUBRE
B13: ERNERO | C13: 50 | D13: =D12+C13 -> 200 | E13: DEBE | G13: NOV | H13: 50
B14: FEBRERO | C14: 50 | D14: =D13+C14 -> 250 | E14: DEBE | G14: DIC | H14: 50 | I14: 150 | J14: DEBE
B15: MARZO | C15: 50 | D15: =D14+C15 -> 300 | E15: DEBE | G15: ENERO | H15: 50 | I15: =H15+I14 -> 200 | J15: DEBE
B16: ABRIL | C16: 50 | D16: =D15+C16 -> 350 | E16: DEBE | G16: FEBRERO | H16: 50 | I16: =H16+I15 -> 250 | J16: DEBE
B17: MAYO | C17: 50 | D17: =D16+C17 -> 400 | E17: DEBE | G17: MARZO | H17: 50 | I17: =H17+I16 -> 300 | J17: DEBE
B18: JUNIO | E18: MOTOS MAL | G18: ABRIL | H18: 50 | I18: =H18+I17 -> 350 | J18: DEBE
B19: JULIO | E19: MOTOS MAL | G19: MAYO | H19: 50 | I19: =H19+I18 -> 400 | J19: DEBE
B20: JULIO | C20: 150 | D20: 250 | E20: PAGO DE TRES MESES | G20: JUNIO | J20: MOTOS MAL
B21: AGOSTO | C21: 50 | D21: 300 | E21: DEBE | G21: JULIO | J21: MOTO MAL
G22: JULIO | H22: 150 | I22: 250 | J22: PAGO DE TRES MESES
G23: AGOSTO | H23: 50 | I23: 300 | J23: DEBE
B24: 45904 | E24: GUARDA MOTO DE ALEJANDRO | G24: 45905 | J24: GUARDA MOTO DE ALEJANDRO
B41: VEHICULO | C41: MOTO ROJA | D41: CEL: 72886615 | E41: Vladimir | G41: VEHICULO | H41: GUINDA | I41: CEL | J41: ENTRO EL 25-7-28
B42: PLACA | C42: 5434NFD | E42: Fecha de pago 10 de cada mes | G42: PLACA | H42: 2235ICI | J42: DELMIRA ORTEGA
B44: FECHA | C44: MONTO | D44: DEBE | E44: OBSERVACIONES | G44: FECHA | H44: MONTO | I44: DEBE | J44: OBSERVACIONES
B45: 45145 | C45: 50 | D45: 0 | E45: - | G45: 45132 | H45: 50 | I45: 0 | J45: -
B46: 45177 | C46: 50 | D46: 0 | G46: 45163 | H46: 50 | I46: 0
B47: 45206 | C47: 50 | G47: 45196 | H47: 50
B48: 45232 | C48: 50 | J48: SE RETIRA
B49: 45275 | C49: 70
B50: 45301 | C50: 70 | G50: 45935 | H50: 60 | I50: 0 | J50: PAGO ADELANTADO
B51: 45343 | C51: 70
B52: 45369 | C52: 70
B53: 45401 | C53: 70
B54: 45420 | C54: 70
B55: 45456 | C55: 70
B56: 45501 | C56: 70
B57: 45522 | C57: 70
B58: Septiembre | C58: 0 | D58: 70
B59: Octubre | C59: 0 | D59: 70 | E59: PAGO 140
B60: 45611 | C60: 70
...

Sheet Hoja1
A1: codigo | B1: estado | C1: nombre | D1: celular | E1: vehiculo | F1: color | G1: marca | H1: placa | I1: fecharegistro | J1: hingreso | K1: hsalida | L1: montoapagar

Sheet Hoja4
A1: Column1 | B1: Column2 | C1: Column3 | D1: Column4 | E1: Column5 | F1: Column6 | G1: Column7 | H1: Column8 | I1: Column9 | J1: Column10 | K1: Column11 | L1: Column12 | M1: Column13 | N1: Column14 | O1: Column15 | P1: Column16 | Q1: Column17
A2: CODIGO | B2: NBSJB515 | G2: CODIGO | H2: BOESFB245 | M2: CODIGO | N2: FEXJO544
A3: ESTADO | B3: VIGENTE | D3: NOMBRE | E3: MARIA ELENA MERCADO | G3: ESTADO | H3: VIGENTE | J3: NOMBRE | K3: ANDREA | M3: ESTADO | N3: VIGENTE | P3: NOMBRE | Q3: EDWIN MONTECINOS
A4: VEHICULO | B4: VAGONETA PEUGOT | G4: VEHICULO | H4: AUTO NISAN | M4: VEHICULO | N4: NISAN VAGON
A5: COLOR | B5: GUINDO | G5: COLOR | H5: PLOMO | M5: COLOR
A6: PLACA | D6: CEL | E6: 70914404 | G6: PLACA | H6: 2361KNA | J6: CELULAR | K6: 6119134 | M6: PLACA | N6: 1758GXK | P6: CELULAR | Q6: 72895433
A7: INGRESO | B7: 0.8125 | C7: SALIDA | D7: 0.3125 | G7: INGRESO | H7: 0.33333333 | I7: SALIDA | J7: 0.33333333 | M7: INGRESO | N7: 0.95833333 | O7: SALE | P7: 0.29166667
A8: FECHA | B8: MONTO | C8: ACUMULADO | D8: DEBE | E8: OBSERVACIONES | G8: FECHA | H8: MONTO | I8: ACUMULADO | J8: DEBE | K8: OBSERVACIONES | M8: FECHA | N8: MONTO | O8: DEBE | P8: ACUMULADO | Q8: OBSERVACIONES
A9: 45763 | E9: INGRESO PAGA CADA 16 | G9: 45121 | H9: 50 | I9: 0 | J9: 0 | K9: ADELANTO DE JULIO | M9: 45086 | N9: 500 | O9: 1500 | P9: 2000 | Q9: 2000 HASTA JUNIO INCLUYE MOTOS
G10: 45122 | H10: 100 | I10: 0 | J10: 0 | K10: pagado julio | M10: 45115 | N10: 300 | O10: 1200 | P10: 1500 | Q10: DEBE 1500 NO PAGO DE JULIO 150
G11: 45183 | H11: 150 | I11: 0 | J11: 0 | M11: 45145 | N11: 500 | O11: 700 | P11: 850 | Q11: MAS JULIO 1200+150 = 1350-500=850
G12: 45209 | H12: 150 | I12: 0 | J12: 0 | M12: AGOSTO | N12: 0 | O12: 1000 | P12: 1000 | Q12: DEBE AGOSTO 850+150=1000
G13: 45244 | H13: 150 | I13: 0 | J13: 0 | M13: SEPTIEMBRE | N13: 0 | O13: 1150 | P13: 1150 | Q13: NO PAGO DE SEPT. 1000+150=1150
G14: 45275 | H14: 150 | M14: OCTUBRE | N14: 300 | O14: 850 | P14: 1000 | Q14: PAGO EN MES OCT. 1150-300=850 MAS NOV 150 =1000
G15: 45306 | H15: 150 | I15: 0 | J15: 0 | N15: 250 | P15: 750 | Q15: no debe
G16: 45337 | H16: 150 | I16: 0 | J16: 0 | M16: 45301 | N16: 150 | P16: 0
G17: 45365 | H17: 150 | I17: 0 | J17: 0 | M17: 45341 | N17: 150 | P17: 300 | Q17: debe
G18: 45399 | H18: 150 | I18: 0 | J18: 0 | M18: 45366 | N18: 300 | O18: 150 | Q18: del mes de marzo
G19: 45429 | H19: 150 | M19: Abril | O19: 150 | P19: 300 | Q19: debe 300
G20: 45454 | H20: 150 | K20: JULIO EN MECANICO | M20: mayo | O20: 150 | P20: 450 | Q20: NO PAGO
G21: 45514 | H21: 150 | M21: Junio | O21: 150 | P21: 600 | Q21: NO PAGO
G22: 45545 | H22: 150 | M22: Julio | P22: 600 | Q22: VEHICULO MAL
G23: 45575 | H23: 150 | M23: Julio | N23: 150 | O23: 450 | P23: 450 | Q23: PAGO DE UN MES
G24: 45606 | H24: 150 | M24: AGOSTO | N24: 200 | O24: 250 | P24: 250 | Q24: PAGO 200, DEBE 250
G25: 45641 | H25: 150 | M25: FECHA | N25: MONTO | O25: DEBE | P25: ACUMULADO | Q25: OBSERVACIONES
M26: 2024
G27: 45675 | H27: 150 | M27: Abril | O27: 150 | P27: 300 | Q27: debe 300
G28: 45701 | H28: 150 | M28: mayo | O28: 150 | P28: 450 | Q28: NO PAGO
G29: 45726 | H29: 150 | M29: Junio | O29: 150 | P29: 600 | Q29: NO PAGO
G30: 45762 | H30: 150 | M30: Julio | P30: 600 | Q30: VEHICULO MAL
M31: Julio | N31: 150 | O31: 450 | P31: 450 | Q31: PAGO DE UN MES
M32: AGOSTO | N32: 200 | O32: 250 | P32: 250 | Q32: PAGO 200, DEBE 250
M33: SEPTIEMBRE | N33: 0 | O33: 250 | P33: 400 | Q33: 250+150 DEBE 400
M34: OCTUBRE | N34: 0 | O34: 400 | P34: 550
M35: NOVIEMBRE | N35: 0 | O35: 550 | P35: 700 | Q35: 550+150 DEBE 700
M36: DICIEMBRE | N36: 700 | O36: 150 | P36: 850 | Q36: NO PAGO
M37: 2025 pago hasta fin de mes
M38: MES | N38: CANCELO | O38: PAGO MES | P38: DEBE | Q38: OBSERVACIONES
M39: ENERO | N39: 0 | O39: 150 | P39: 1000 | Q39: 850+150 =1000 no pago del mes
M40: FEBRERO | N40: 0 | O40: 150 | P40: 1150 | Q40: 1000+150=1150 no pago del mes
...
